Workbook
Name AirLogistics: 'Ref_Common'!$T$29:$T$31
Name AlorGajahAyerLimau: 'Ref_Shelter'!$C$1186:$C$1187
Name AlorGajahDurianTunggal: 'Ref_Shelter'!$D$1186:$D$1191
Name AlorGajahGadek: 'Ref_Shelter'!$E$1186
Name AlorGajahKulaiLinggi: 'Ref_Shelter'!$F$1186
Name AlorGajahLendu: 'Ref_Shelter'!$G$1186:$G$1187
Name AlorGajahMachap: 'Ref_Shelter'!$H$1186:$H$1190
Name AlorGajahRembia: 'Ref_Shelter'!$I$1186:$I$1188
Name AlorGajahTabohNaning: 'Ref_Shelter'!$J$1186
Name AlorGajahTanjungBidara: 'Ref_Shelter'!$K$1186
Name Arau: 'Ref_Shelter'!$C$2101:$C$2123
Name BachokBachok: 'Ref_Shelter'!$C$957:$C$962
Name BalingBakai: 'Ref_Shelter'!$C$291:$C$293
Name BalingBaling: 'Ref_Shelter'!$D$291:$D$348
Name BalingKualaKetil: 'Ref_Shelter'!$E$291:$E$292
Name BalingMalau: 'Ref_Shelter'!$F$291:$F$292
Name BandarBaharuBandarBaharu: 'Ref_Shelter'!$C$368:$C$388
Name BaratDayaBaratDaya: 'Ref_Shelter'!$C$2139:$C$2152
Name BatangPadangBidor: 'Ref_Shelter'!$C$1852
Name BatangPadangChenderiang: 'Ref_Shelter'!$D$1852
Name BatangPadangSlimRiver: 'Ref_Shelter'!$E$1852:$E$1854
Name BatangPadangSungkai: 'Ref_Shelter'!$F$1852
Name BatangPadangTanjungMalim: 'Ref_Shelter'!$G$1852:$G$1853
Name BatangPadangTapah: 'Ref_Shelter'!$H$1852
Name BatangPadangTemoh: 'Ref_Shelter'!$I$1852:$I$1853
Name BatuPahatAyerHitam: 'Ref_Shelter'!$C$8
Name BatuPahatBagan: 'Ref_Shelter'!$D$8
Name BatuPahatBandarPenggaram: 'Ref_Shelter'!$E$8:$E$14
Name BatuPahatMinyakBeku: 'Ref_Shelter'!$F$8
Name BatuPahatParitRaja: 'Ref_Shelter'!$G$8:$G$27
Name BatuPahatPtYaani: 'Ref_Shelter'!$H$8:$H$23
Name BatuPahatRengit: 'Ref_Shelter'!$I$8:$I$14
Name BatuPahatSemarang: 'Ref_Shelter'!$J$8:$J$21
Name BatuPahatSemerah: 'Ref_Shelter'!$K$8:$K$22
Name BatuPahatSenggarang: 'Ref_Shelter'!$L$8:$L$17
Name BatuPahatSimpangKanan: 'Ref_Shelter'!$M$8
Name BatuPahatSriMedan: 'Ref_Shelter'!$N$8:$N$31
Name BatuPahatSungaiKluang: 'Ref_Shelter'!$O$8
Name BatuPahatYongPeng: 'Ref_Shelter'!$P$8:$P$17
Name BauBau: 'Ref_Shelter'!$C$2522:$C$2524
Name BeaufortNone: 'Ref_Shelter'!$C$2347:$C$2348
Name BentongBentong: 'Ref_Shelter'!$C$1500:$C$1511
Name BentongPelangai: 'Ref_Shelter'!$D$1500:$D$1510
Name BentongSabai: 'Ref_Shelter'!$E$1500:$E$1505
Name BeraBera: 'Ref_Shelter'!$C$1520:$C$1559
Name BeraMengkarak: 'Ref_Shelter'!$D$1520:$D$1521
Name BeraTriang: 'Ref_Shelter'!$E$1520
Name BesutHuluBesut: 'Ref_Shelter'!$C$2929:$C$2967
Name BesutJabi: 'Ref_Shelter'!$D$2929:$D$2941
Name BesutJerteh: 'Ref_Shelter'!$E$2929:$E$2949
Name BesutKampongRaja: 'Ref_Shelter'!$F$2929:$F$2940
Name BesutKualaBesut: 'Ref_Shelter'!$G$2929:$G$2940
Name BintuluBintulu: 'Ref_Shelter'!$C$2542:$C$2546
Name CameronHighlandsBurau: 'Ref_Shelter'!$E$1568
Name CameronHighlandsTanahRata: 'Ref_Shelter'!$C$1568:$C$1594
Name CameronHighlandsUluCheka: 'Ref_Shelter'!$D$1568:$D$1570
Name CasualtyAge: 'Ref_Common'!$E$6:$E$9
Name CasualtyRace: 'Ref_Common'!$F$6:$F$10
Name CasualtySex: 'Ref_Common'!$D$6:$D$7
Name CasualtyStatus: 'Ref_Common'!$B$10:$B$12

Sheet General_Info
C3: Nama Bencana | H3: [Contoh : Banjir Di Johor Oktober 2013]
C5: Negeri | G5: [Sila Pilih Negeri Dari Drop-Down]
C7: Tarikh & Masa | G7: [ Format : dd/mm/yyyy hh:mm AM/PM ]
C9: Ringkasan Laporan
C15: Hal-hal lain
N16: General_Info | O16: FALSE
N17: ShelterStatus | O17: FALSE
N18: Mobilization | O18: FALSE
C19: Lampiran Yang Dikemaskini (Tanda yg dikemaskini sahaja) | N19: Damage_Casualties | O19: FALSE
N20: CasualtiesDetail | O20: FALSE
N21: Damage_Infrastructure(Govt) | O21: FALSE
N22: Damage_Infrastructure(Private) | O22: FALSE
C23: Disediakan Oleh | N23: Aqua,Agri,LiveStockDamage | O23: FALSE
C24: Nama | N24: ClosedRoad | O24: FALSE
C25: Jawatan
C26: No Tel
C28: Disahkan Oleh
C29: Nama
C30: Jawatan
C31: No Tel

Sheet ShelterStatus
D1: =General_Info!D5 -> Terengganu
A2: -
B3: Daerah | C3: Mukim | D3: Nama Pusat Pemindahan | E3: Waktu Operasi (Tarikh & Masa) | G3: Jumlah Mangsa Pemindahan | H3: Jumlah Keluarga Di Pusat Pemindahan | I3: Anggaran Mangsa di Luar Pusat Pemindahan (Jika Ada) | J3: Jantina | L3: Terperinci | P3: Pengurus Pusat Pemindahan | Q3: Jawatan | R3: Nombor Telefon
E4: [ Format : dd/mm/yyyy hh:mm AM/PM ] | L4: Dewasa | N4: Kanak-Kanak | S4: DL | T4: DP | U4: WE (L) | V4: WE (P) | W4: KL | X4: KP | Y4: BL | Z4: BP | AA4: OKU (L) | AB4: OKU (P) | AC4: OKU (KL) | AD4: OKU (KP)
E5: Buka | F5: Tutup | J5: Lelaki | K5: Perempuan | L5: Lelaki | M5: Perempuan | N5: Lelaki | O5: Perempuan
G6: =J6+K6 | J6: =L6+N6 | K6: =M6+O6 | L6: =S6+U6+AA6 | M6: =T6+V6+AB6 | N6: =W6+Y6+AC6 | O6: =X6+Z6+AD6
A7: JUMLAH

Sheet Mobilization
B3: Agensi/NGO | C3: Jenis Tindak Balas | D3: Kekuatan Ahli (Contoh : 40) | E3: Lojistik | K3: Tarikh Mula Operasi [Format : dd/mm/yyyy] | L3: Tarikh Tamat Operasi [Format : dd/mm/yyyy] | M3: Catatan
E4: Darat | G4: Air | I4: Udara
E5: Jenis | F5: Kuantiti (Unit) | G5: Jenis | H5: Kuantiti (Unit) | I5: Jenis | J5: Kuantiti (Unit)

Sheet CasualtiesDetail
B3: Nama Mangsa | C3: Alamat | D3: Kategori | E3: Umur | F3: Jantina | G3: Bangsa | H3: Catatan | I3: Sebab Kematian

Sheet Damage_Casualties
D1: =General_Info!D5 -> Terengganu
B3: Daerah | C3: Kategori | D3: Jantina | F3: Terperinci | J3: Jumlah Keseluruhan
D4: Lelaki | E4: Perempuan | F4: Dewasa | H4: Kanak-Kanak
F5: Lelaki | G5: Perempuan | H5: Lelaki | I5: Perempuan
D7: =SUM(F7,H7) | E7: =SUM(G7,I7) | J7: =SUM(D7,E7)
D8: =SUM(F8,H8) | E8: =SUM(G8,I8) | J8: =SUM(D8,E8)
D9: =SUM(F9,H9) | E9: =SUM(G9,I9) | J9: =SUM(D9,E9)
D10: =SUM(F10,H10) | E10: =SUM(G10,I10) | J10: =SUM(D10,E10)
D11: =SUM(F11,H11) | E11: =SUM(G11,I11) | J11: =SUM(D11,E11)
D12: =SUM(F12,H12) | E12: =SUM(G12,I12) | J12: =SUM(D12,E12)
D13: =SUM(F13,H13) | E13: =SUM(G13,I13) | J13: =SUM(D13,E13)
D14: =SUM(F14,H14) | E14: =SUM(G14,I14) | J14: =SUM(D14,E14)
D15: =SUM(F15,H15) | E15: =SUM(G15,I15) | J15: =SUM(D15,E15)
D16: =SUM(F16,H16) | E16: =SUM(G16,I16) | J16: =SUM(D16,E16)
D17: =SUM(F17,H17) | E17: =SUM(G17,I17) | J17: =SUM(D17,E17)
D18: =SUM(F18,H18) | E18: =SUM(G18,I18) | J18: =SUM(D18,E18)
... D70: =SUM(F70,H70) | E70: =SUM(G70,I70) | J70: =SUM(D70,E70)
D72: =SUM(D7:D71) | E72: =SUM(E7:E71) | J72: =SUM(J7:J71)

Sheet Damage_Infrastructure(Govt)
D1: =General_Info!D5 -> Terengganu
B3: Daerah | C3: Kategori | D3: Bangunan Terjejas (unit) | F3: Hak Milik | G3: Perincian Kerosakan/Kemusnahan
D4: Rosak | E4: Musnah

Sheet Aqua,Agri,LivestockDamage
D1: =General_Info!D5 -> Terengganu
B3: Daerah | C3: Alamat | D3: Kategori | E3: Sub-Kategori | F3: Punca Kerosakan | G3: Bilangan Petani/Penternak Terlibat | H3: Anggaran Kawasan Terjejas (ha) | I3: Jumlah Terjejas (Sangkar/Petak/Ternakan) | J3: Catatan

Sheet Damage_Infrastructure(Private)
D1: =General_Info!D5 -> Terengganu
B3: Daerah | C3: Kategori | D3: Bangunan Terjejas (unit) | F3: Hak Milik | G3: Perincian Kerosakan
D4: Rosak | E4: Musnah

Sheet ClosedRoad
D1: =General_Info!$D$5 -> Terengganu
B3: Daerah | C3: Mukim | D3: Nama Laluan/Jalan/Lebuhraya | E3: Lokasi Penutupan Jalan | F3: Laluan Alternatif | G3: Koordinat | I3: Tarikh/Masa Penutupan Bermula [ Format : dd/mm/yyyy hh:mm AM/PM ] | J3: Tarikh/Masa Penutupan Berakhir [ Format : dd/mm/yyyy hh:mm AM/PM ] | K3: URL | L3: Punca Penutupan
G4: Latitude | H4: Longitude

Sheet Ref_District
B2: < Basic Data 01.Distrct >
B4: State | D4: District | U4: Sub District - Johor | AF4: Sub District - Kedah | AT4: Sub District - Melaka | AX4: Sub District - Negeri Sembilan | BI4: Sub District - Kelantan | BU4: Sub District - Kuala Lumpur | BY4: Sub District - Labuan | CA4: Sub District - Pahang | CN4: Sub District - Pulau Pinang | CX4: Sub District - Putrajaya | CZ4: Sub District - Sabah | ED4: Sub District - Sarawak | FL4: Sub District - Selangor | FZ4: Sub District - Terengganu | GJ4: Sub District - Perak | GW4: Sub District - Perlis
B5: Johor | D5: Johor | E5: Kedah | F5: Melaka | G5: Negeri Sembilan | H5: Kelantan | I5: Kuala Lumpur | J5: Labuan | K5: Pahang | L5: Pulau Pinang | M5: Putrajaya | N5: Sabah | O5: Sarawak | P5: Selangor | Q5: Terengganu | R5: Perak | S5: Perlis | U5: Batu Pahat | V5: Johor Bahru | W5: Kluang | X5: Kota Tinggi | Y5: Kulaijaya | Z5: Ledang | AA5: Mersing | AB5: Muar | AC5: Pontian | AD5: Segamat | AF5: Baling | AG5: Bandar Baharu | AH5: Kota Setar | AI5: Kuala Muda | AJ5: Kubang Pasu | AK5: Kulim | AL5: Langkawi | AM5: Padang Terap | AN5: Pendang | AO5: Pokok Sena | AP5: Sik | AQ5: Sungai Petani | AR5: Yan | AT5: Alor Gajah | AU5: Jasin | AV5: Melaka Tengah | AX5: Alor Gajah | AY5: Gemas | AZ5: Jelebu | BA5: Jempol | BB5: Kuala Pilah | BC5: Nilai | BD5: Port Dickson | BE5: Rembau | BF5: Seremban | BG5: Tampin | BI5: Bachok | BJ5: Gua Musang | BK5: Jeli | BL5: Jerteh | BM5: Kota Bharu | BN5: Kuala Krai | BO5: Machang | BP5: Pasir Mas | BQ5: Pasir Puteh | BR5: Tanah Merah | BS5: Tumpat | BU5: Cheras | BV5: Gombak | BW5: Kuala Lumpur | BY5: Labuan | CA5: Bentong | CB5: Bera | CC5: Cameron Highlands | CD5: Jerantut | CE5: Kuala Lipis | CF5: Kuantan | CG5: Lipis | CH5: Maran | CI5: Pekan | CJ5: Raub | CK5: Rompin | CL5: Temerloh | CN5: Barat Daya | CO5: Bukit Gedong | CP5: Butterworth | CQ5: Lebuh Fell | CR5: Seberang Perai Selatan | CS5: Seberang Perai Tengah | CT5: Seberang Perai Utara | CU5: Sungai Ara | CV5: Timur Laut | CX5: Putrajaya | CZ5: Beaufort | DA5: Beluran | DB5: Kelabakan | DC5: Keningau | DD5: Kinabatangan | DE5: Kota Belud | DF5: Kota Kinabalu | DG5: Kota Marudu | DH5: Kuala Penyu | DI5: Kudat | DJ5: Kunak | DK5: Lahad Datu | DL5: Nabawan | DM5: Papar | DN5: Penampang | DO5: Pensiangan | DP5: Pitas | DQ5: Ranau | DR5: Sandakan | DS5: Semporna | DT5: Sipitang | DU5: Sook | DV5: Tambunan | DW5: Tawau | DX5: Teluk Sepanggar | DY5: Telupid | DZ5: Tenom | EA5: Tongod | EB5: Tuaran | ED5: Asajaya | EE5: Bakelalan | EF5: Baram | EG5: Bau | EH5: Belaga | EI5: Betong | EJ5: Bintulu | EK5: Dalat | EL5: Daro | EM5: Julau | EN5: Kanowit | EO5: Kapit | EP5: Kuching | EQ5: Lawas | ER5: Limbang | ES5: Lubok Antu | ET5: Lundu | EU5: Marudi | EV5: Matu | EW5: Meradong | EX5: Miri | EY5: Muara Tuang | EZ5: Mukah | FA5: Pakan | FB5: Samarahan | FC5: Saratok | FD5: Sarikei | FE5: Serian | FF5: Sibu | FG5: Simunjan | FH5: Song | FI5: Sri Aman | FJ5: Tatau | FL5: Batu Caves | FM5: Gombak | FN5: Hulu Langat | FO5: Hulu Selangor | FP5: Klang | FQ5: Kuala Langat | FR5: Kuala Selangor | FS5: Petaling | FT5: Rawang | FU5: Sabak Bernam | FV5: Selatan Selangor | FW5: Sepang | FX5: Sungai Buloh | FZ5: Besut | GA5: Dungun | GB5: Hulu Terengganu | GC5: Kemaman | GD5: Kerteh | GE5: Kota Bharu | GF5: Kuala Terengganu | GG5: Marang | GH5: Setiu | GJ5: Batang Padang | GK5: Hilir Perak | GL5: Hulu Perak | GM5: Kampar | GN5: Kerian | GO5: Kinta | GP5: Kuala Kangsar | GQ5: Larut dan Matang | GR5: Manjung | GS5: Pengkalan Hulu | GT5: Perak Tengah | GU5: Taiping | GW5: Arau | GX5: Kangar | GY5: Perlis
B6: Kedah | D6: Batu Pahat | E6: Baling | F6: Alor Gajah | G6: Alor Gajah | H6: Bachok | I6: Cheras | J6: Labuan | K6: Bentong | L6: Barat Daya | M6: Putrajaya | N6: Beaufort | O6: Asajaya | P6: Batu Caves | Q6: Besut | R6: Batang Padang | S6: Arau | U6: Bagan | V6: Sungai Tiram | W6: Kahang | X6: Johor Lama | Y6: Senai | Z6: Tangkak | AA6: Mersing | AB6: Ayer Hitam | AC6: Benut | AD6: Bandar Segamat | AF6: Bakai | AG6: Bagan Samak | AH6: Alor Malai | AI6: Bujang | AJ6: Ah | AK6: Bagan Sena | AL6: Ayer Hangat | AM6: Batang Tunggang Kanan | AN6: Ayer Puteh | AO6: Jabi | AP6: Jeneri | AQ6: Yan | AR6: Dulang | AT6: Ayer Pa'Abas | AU6: Ayer Panas | AV6: Alai | AX6: 4 SKN RAJD | AY6: MPLTD | AZ6: Gelami Lemi | BA6: Jelai | BB6: Ampang Tinggi | BC6: Nilai | BD6: Jimah | BE6: Batu Hampar | BF6: Ampangan | BG6: Ayer Kuning | BI6: Beklam | BJ6: Galas | BK6: Batu Melintang | BL6: Gong Kedak | BM6: Badang | BN6: Batu Mengkebang | BO6: Labok | BP6: Alor Pasir | BQ6: Padang Pak Amat | BR6: Kusial | BS6: Jal Besar | BU6: Sungai Besi | BV6: Wardieburn | BW6: Ampang | BY6: None | CA6: Bentong | CB6: Bera | CC6: Ringlet | CD6: Burau | CE6: Raub | CF6: Beserah | CG6: Batu Yon | CH6: Bukit Segumpal | CI6: Bebar | CJ6: Batu Talam | CK6: Endau | CL6: Bangau | CN6: Barat Daya | CO6: 2 DIV | CP6: KTU Butterworth | CQ6: 2 REJ KPTD | CR6: Mukim 1 | CS6: Mukim 1 | CT6: Mukim 1 | CU6: 2 RAMD | CV6: Paya Terubong | CX6: Presint 4 | CZ6: None | DA6: None | DB6: None | DC6: None | DD6: None | DE6: None | DF6: 5 Bgd | DG6: None | DH6: None | DI6: None | DJ6: None | DK6: None | DL6: None | DM6: None | DN6: None | DO6: None | DP6: None | DQ6: None | DR6: 5 Bgd | DS6: None | DT6: None | DU6: None | DV6: None | DW6: 5 Bgd | DX6: None | DY6: None | DZ6: None | EA6: None | EB6: None | ED6: Asajaya | EE6: Bario | EF6: Baram | EG6: Bau | EH6: Belaga | EI6: Betong | EJ6: Bintulu | EK6: Dalat | EL6: Daro | EM6: Julau | EN6: Kanowit | EO6: Kapit | EP6: Kuching | EQ6: Lawas | ER6: Limbang | ES6: Lubok Antu | ET6: Lundu | EU6: Marudi | EV6: Matu | EW6: Meradong | EX6: Miri | EY6: Muara Tuang | EZ6: Mukah | FA6: Sarikei | FB6: Samarahan | FC6: Saratok | FD6: Sarikei | FE6: Serian | FF6: Sibu | FG6: Simunjan | FH6: Song | FI6: Sri Aman | FJ6: Tatau | FL6: MPLTD | FM6: Batu Caves | FN6: Ampang | FO6: Ampang Pechah | FP6: Kapar | FQ6: Bandar | FR6: Api-Api | FS6: Bukit Raja | FT6: Ulu Selangor | FU6: Bagan Nakhoda Omar | FV6: 1 Bgd | FW6: Dengkil | FX6: 11 BGD | FZ6: Bukit Kenak | GA6: Kuala Abang | GB6: Jenagur | GC6: Banggul | GD6: Kemaman | GE6: 8 Bgd | GF6: Atas Tol | GG6: Jerung | GH6: Hulu Setiu | GJ6: Batang Padang | GK6: Bagan Datoh | GL6: Belukar Semang | GM6: Bandar Baru Kampar | GN6: Bagan Serai | GO6: Belanja | GP6: Chegar Galah | GQ6: Asam Kumbang | GR6: Beruas | GS6: 2 Bgd | GT6: Bandar | GU6: 2 Bgd | GW6: 4 RRD | GX6: BGD Sempadan | GY6: Abi
B7: Melaka | D7: Johor Bahru | E7: Bandar Baharu | F7: Jasin | G7: Gemas | H7: Gua Musang | I7: Gombak | K7: Bera | L7: Bukit Gedong | N7: Beluran | O7: Bakelalan | P7: Gombak | Q7: Dungun | R7: Hilir Perak | S7: Kangar | U7: Chaah Bahru | V7: Plentong | W7: Kluang | X7: Kambau | Y7: Kulai | Z7: Serom | AA7: Triang | AB7: Bandar | AC7: Sungai Pinggan | AD7: Sungai Segamat | AF7: Baling | AG7: Relau | AH7: Alor Merah | AI7: Bukit Meriam | AJ7: Binjal | AK7: Junjong | AL7: Bohor | AM7: Batang Tunggang Kiri | AN7: Bukit Raya | AP7: Sik | AQ7: Kuala Muda | AR7: Sala Besar | AT7: Belimbing | AU7: Batang Malaka | AV7: Ayer Molek | AZ7: Kenaboi | BA7: Kuala Jempol | BB7: Johol | BD7: Linggi | BE7: Bongek | BF7: Labu | BG7: Gemas | BI7: Gunong | BJ7: Bertam | BK7: Jeli | BM7: Banggu | BN7: Olak Jeram | BO7: Panyit | BP7: Bunut Susu | BQ7: Bukit Abal | BR7: Jedok | BS7: Kebakat | BW7: Bandar Kuala Lumpur | CA7: Pelangai | CB7: Triang | CC7: Tanah Rata | CD7: Kelola | CE7: Kuala Lipis | CF7: Kuala Kuantan | CG7: Budu | CH7: Chenor | CI7: Ganchong | CJ7: Dong | CK7: Keratong | CL7: Jenderak | CN7: Bukit Gedong | CP7: TLDM | CQ7: REJ 509 AW | CR7: Mukim 2 | CS7: Bandar Prai (Mukim 1A) | CT7: Mukim 2 | CU7: 2 RSD | CV7: Bkt Paya Terubong | DF7: 5 SKN RAJD | ED7: Semera | EE7: Bakelalan | EF7: Kelabit | EH7: Sungai Asap | EI7: Pusa | EJ7: Sebauh | EK7: Oya | EL7: Tekajong | EM7: Pakan | EO7: Nanga Merit | EP7: Padawan | EQ7: Sundar | ER7: Nanga Medamit | ES7: Engkilili | ET7: Sematan | EU7: Beluru | EV7: Igan | EW7: Bintangor | EX7: Sibuti | EZ7: Balingian | FA7: Pakan | FB7: Kota Samarahan | FC7: Kabong | FD7: Belawai | FE7: Tebedu | FF7: Mukah | FG7: Sebuyau | FH7: Chemenong | FI7: Maludam | FM7: Rawang | FN7: Beranang | FO7: Batang Kali | FP7: Klang | FQ7: Batu | FR7: Batang Berjuntai | FS7: Damansara | FT7: Erskine | FU7: Pancang Bedena | FW7: Labu | FX7: 12 Bde | FZ7: Bukit Peteri | GA7: Besul | GB7: Kuala Berang | GC7: Binjai | GD7: Dungun | GF7: Batu Buruk | GG7: Mercang | GH7: Pantai | GJ7: Bidor | GK7: Changkat Jong | GL7: Belum | GM7: Malim Nawar | GN7: Bagan Tiang | GO7: Kampar | GP7: Kampung Buaya | GQ7: Batu Kurau | GR7: Lekir | GT7: Belanja | GW7: 6 SKN RAJD | GY7: Arau
B8: Negeri Sembilan | D8: Kluang | E8: Kota Setar | F8: Melaka Tengah | G8: Jelebu | H8: Jeli | I8: Kuala Lumpur | K8: Cameron Highlands | L8: Butterworth | N8: Kelabakan | O8: Baram | P8: Hulu Langat | Q8: Hulu Terengganu | R8: Hulu Perak | S8: Perlis | U8: Kampong Bahru | V8: Pulai | W8: Layang-Layang | X8: Pantai Timur | Y8: Bukit Batu | Z8: Grisek | AA8: Tenglu | AB8: Bukit Kepong | AC8: Ayer Baloi | AD8: Jemantah | AF8: Bongor | AG8: Kuala Selama | AH8: Bukit Lada | AI8: Gurun | AJ8: Bukit Tinggi | AK8: Karangan | AL8: Kedawang | AM8: Belimbing Kanan | AN8: Guar Kepayang | AP8: Sok | AQ8: Sik | AR8: Singkir | AT8: Beringin | AU8: Bukit Senggeh | AV8: Bachang | AZ8: Kuala Kelawang | BA8: Rompin | BB8: Juasseh | BD8: Pasir Panjang | BE8: Chembong | BF8: Lenggeng | BG8: Gemencheh | BI8: Gunong Timur | BJ8: Chiku | BK8: Belimbing | BM8: Beta | BN8: Dabong | BO8: Pulai Chondong | BP8: Chetok | BQ8: Bukit Awang | BR8: Ulu Kusial | BS8: Pengkalan Kubor | BW8: Batu | CA8: Sabai | CB8: Sungai Kemahal | CC8: Ulu Telom | CD8: Kuala Tembeling | CE8: Brinchang | CF8: Penor | CG8: Cheka | CH8: Kertau | CI8: Kuala Pahang | CJ8: Gali | CK8: Pontian | CL8: Kerdau | CN8: Butterworth | CR8: Mukim 3 | CS8: Mukim 2 | CT8: Mukim 3 | CV8: Bkt Ayer Itam | DF8: Teluk Sepanggar | ED8: Sadong Jaya | EI8: Debak | EJ8: Tubau | EK8: Nanga Boh | EL8: Tanjung Manis | EM8: Lassi | EP8: Siburan | EQ8: Trusan | ET8: Sampadi | EU8: Long Lama | EV8: Tian | EX8: Niah-Suai | FB8: 3 Bgd | FC8: Roban | FD8: Tanjung Manis | FE8: Triboh | FF8: Sarikei | FI8: Lingga | FM8: Setapak | FN8: Cheras | FO8: Buloh Telor | FP8: Bandar Klang | FQ8: Kelanang | FR8: Ijok | FS8: Petaling | FU8: Pasir Panjang | FW8: Sepang | FX8: Sungai Buloh | FZ8: Jabi | GA8: Jengai | GB8: Kuala Telemung | GC8: Bandi | GF8: Batu Rakit | GG8: Pulau Kerengga | GH8: Guntung | GJ8: Chenderiang | GK8: Durian Sebatang | GL8: Durian Pipit | GM8: Gopeng | GN8: Beriah | GO8: Sungai Raia | GP8: Kota Lama Kanan | GQ8: Bukit Gantang | GR8: Lumut | GT8: Bota | GW8: REJ 504 AW | GY8: Beseri
B9: Kelantan | D9: Kota Tinggi | E9: Kuala Muda | G9: Jempol | H9: Jerteh | K9: Jerantut | L9: Lebuh Fell | N9: Keningau | O9: Bau | P9: Hulu Selangor | Q9: Kemaman | R9: Kampar | U9: Linau | V9: Tanjung Kupang | W9: Machap | X9: Kota Tinggi | Y9: Bukit Permai | Z9: Bukit Serampang | AA9: Penyabong | AB9: Jalan Bakri | AC9: Api-api | AD9: Gemereh | AF9: Kupang | AG9: Serdang | AH9: Bukit Pinang | AI9: Haji Kudong | AJ9: Gelong | AK9: Keladi | AL9: Kuah | AM9: Belimbing Kiri | AN9: Padang Kerbau | AP9: Belantik | AR9: Sungai Daun | AT9: Brisu | AU9: Chabau | AV9: Balai Panjang | AZ9: Peradong | BA9: Serting Hilir | BB9: Kepis | BD9: Port Dickson | BE9: Chengkau | BF9: Pantai | BG9: Keru | BI9: Mahligai | BJ9: Bandar baru gua musang | BK9: Kuala Balah | BM9: Kadok | BN9: Kuala Krai | BO9: Pangkal Meleret | BP9: Gual Periok | BQ9: Bukit Jawa | BR9: Tanah Merah | BS9: Sungai Pinang | BW9: Cheras | CA9: Tras | CB9: Mengkarak | CC9: Tringkap | CD9: Pedah | CE9: Kuala Lanar | CF9: Sungai Karang | CG9: Gua | CH9: Luit | CI9: Langgar | CJ9: Sega | CK9: Rompin | CL9: Lebak | CN9: Lebuh Fell | CR9: Mukim 4 | CS9: Mukim 3 | CT9: Mukim 4 | CV9: Ayer Itam | EI9: Spaoh | EK9: Mukah | EL9: Semah | EP9: Kota Sentosa | EQ9: Merap | EU9: Mulu | EV9: Sibu | EX9: Bekenu | FC9: Budu | FE9: Tebakang | FF9: Kapit | FI9: Pantu | FM9: Ulu Kelang | FN9: Kajang | FO9: Kalumpang | FP9: Telok Gong | FQ9: Morib | FR9: Jeram | FS9: Bandar Petaling Jaya | FU9: Sabak | FW9: Salak Tinggi | FZ9: Kampong Raja | GA9: Jerangau | GB9: Penghulu Diman | GC9: Cukai | GF9: Belara | GG9: Rusila | GH9: Tasik | GJ9: Slim | GK9: Hutan Melintang | GL9: Grik | GN9: Gunong Semanggol | GO9: Sungai Terap | GP9: Kota Lama Kiri | GQ9: Ulu Ijok | GR9: Pengkalan Baharu | GT9: Jaya Baharu | GY9: Chuping
B10: Kuala Lumpur | D10: Kulaijaya | E10: Kubang Pasu | G10: Kuala Pilah | H10: Kota Bharu | K10: Kuala Lipis | L10: Seberang Perai Selatan | N10: Kinabatangan | O10: Belaga | P10: Klang | Q10: Kerteh | R10: Kerian | U10: Lubok | V10: Mukim Bandar | W10: Niyor | X10: Pengerang | Y10: Ayer Hitam | Z10: Kundang | AA10: Tenggaroh | AB10: Jorak | AC10: Pontian | AD10: Jabi | AF10: Pulai | AG10: Sungai Batu | AH10: Derga | AI10: Kota | AJ10: Husba | AK10: Kulim | AL10: Padang Masirat | AM10: Kurong Hitam | AN10: Padang Peliang | AP10: Bendang Man | AR10: Yan | AT10: Tanjung Tuan | AU10: Chin Chin | AV10: Batu Berendam | AZ10: Pertang | BA10: Serting Ulu | BB10: Langkap | BD10: Si Rusa | BE10: Gadong | BF10: Rantau | BG10: Repah | BI10: Perupok | BJ10: Gua Musang | BK10: Machang | BM10: Kemumin | BN10: Kemubu | BO10: Temangan | BP10: Kangkong | BQ10: Gong Datok | BR10: Bukit Panau | BS10: Terbok | BW10: Kuala Lumpur | CA10: Telemong | CB10: Mayam | CC10: Kuala Terla | CD10: Pulau Tawar | CE10: Kerambit | CF10: Ulu Kuantan | CG10: Kechau | CH10: Sungai Kemap | CI10: Lepar | CJ10: Semantan Ulu | CK10: Tioman | CL10: Lipat Kajang | CN10: Seberang Perai Selatan | CR10: Mukim 5 | CS10: Mukim 4 | CT10: Mukim 5 | CV10: Batu Feringgi | EI10: Sri Aman | EK10: Medong | EL10: Paloh | EP10: Bunuk | EU10: Long lellang | EX10: 9 Bgd | FE10: Tarat | FF10: Selangau | FI10: Betong | FM10: Selayang | FN10: Semenyih | FO10: Kerling | FP10: Sungai Udang | FQ10: Tanjong Dua Belas | FR10: Kuala Selangor | FS10: Shah Alam | FU10: Sungai Panjang | FW10: Bagan Lalang | FZ10: Keluang | GA10: Kuala Dungun | GB10: Tanggul | GC10: Kemasik | GF10: Bukit Besar | GG10: Bukit Payung | GH10: Caluk | GJ10: Sungkai | GK10: Labu Kubong | GL10: Kenering | GN10: Kualau Kurau | GO10: Tanjong Tualang | GP10: Lubok Merbau | GQ10: Jebong | GR10: Sitiawan | GT10: Kampong Gajah | GY10: Jejawi
B11: Labuan | D11: Ledang | E11: Kulim | G11: Nilai | H11: Kuala Krai | K11: Kuantan | L11: Seberang Perai Tengah | N11: Kota Belud | O11: Betong | P11: Kuala Langat | Q11: Kota Bharu | R11: Kinta | U11: Minyak Beku | V11: Jelutong | W11: Paloh | X11: Sedili Besar | Y11: Kulaijaya | Z11: Kesang | AA11: Jemaluang | AB11: Lenga | AC11: Jeram Batu | AD11: Sermin | AF11: Siong | AG11: Sungai Kechil | AH11: Gunong | AI11: Kuala | AJ11: Jeram | AK11: Lunas | AL11: Ulu Melaka | AM11: Padang Temak | AN11: Padang Pusing | AP11: Charok | AR11: Gelam | AT11: Cape Rachado | AU11: Chohong | AV11: Bertam | AZ11: Teriang Hilir | BA11: Seri Jempol | BB11: Parit Tinggi | BD11: Telok Kemang | BE11: Kundor | BF11: Rasah | BG11: Tampin Tengah | BI11: Melawi | BJ11: Kuala Betis | BK11: Kalai | BM11: Kota | BN11: Manek Urai | BO11: Ulu Sat | BP11: Kuala Lemal | BQ11: Jeram | BR11: Machang | BS11: Tumpat | BW11: Petaling | CA11: Mempaga | CB11: Kumai | CC11: Cameron Highlands | CD11: Tebing Tinggi | CE11: 8 RAMD | CF11: Ulu Lepar | CG11: Kuala Lipis | CH11: Jengka | CI11: Pahang Tua | CJ11: Teras | CK11: Muadzam Shah | CL11: Mentakab | CN11: Seberang Perai Tengah | CR11: Mukim 6 | CS11: Mukim 5 | CT11: Mukim 6 | CV11: Tanjong Tokong | EI11: 3 Bgd | EL11: Kuala Rajang | EP11: Batu Kawa | EU11: Long seridan | FE11: Ringin | FF11: Lanang | FI11: Lubok Antu | FM11: Gombak | FN11: Ulu Langat | FO11: Kuala Kalumpang | FP11: Sementa | FQ11: Telok Panglima Garang | FR11: Tanjung Karang | FS11: Subang | FU11: Sungai Besar | FW11: Cyberjaya | FZ11: Kerandang | GA11: Kuala Paka | GB11: Tersat | GC11: Kerteh | GF11: Cabang Tiga | GG11: Alur Limbat | GH11: Merang | GJ11: Ulu Bernam Barat | GK11: Rungkup | GL11: Kerunai | GN11: Parit Buntar | GO11: Teja | GP11: Pulau Kamiri | GQ11: Kamunting | GR11: Seri Manjung | GT11: Kota Setia | GY11: Kayang
B12: Pahang | D12: Mersing | E12: Langkawi | G12: Port Dickson | H12: Machang | K12: Lipis | L12: Seberang Perai Utara | N12: Kota Kinabalu | O12: Bintulu | P12: Kuala Selangor | Q12: Kuala Terengganu | R12: Kuala Kangsar | U12: Peserai | V12: Bandar Johor Bahru | W12: Rengam | X12: Sedili Kechil | Y12: Inas | Z12: Jementah | AA12: Pulau-Pulau | AB12: Parit Bakar | AC12: Pengkalan Raja | AD12: Buloh Kasap | AF12: Tawar | AG12: Permatang Pasir | AH12: Hutan Kampong | AI12: Merbok | AJ12: Jerlun | AK12: Mahang | AL12: Langkawi | AM12: Padang Terap Kanan | AN12: Rambai | AP12: Chong | AR12: Guar Chempedak | AT12: Durian Tunggal | AU12: Jasin | AV12: Bukit Baru | AZ12: Hulu Kelawang | BA12: Kuala Pilah | BB12: Pilah | BD12: Tampin | BE12: Legong Hilir | BF12: Seremban | BG12: Tebong | BI12: Repek | BJ12: Limau Kasturi | BK12: Ayer Lanas | BM12: Limbat | BN12: Bunut Saih | BO12: Machang | BP12: Kubang Gadong | BQ12: Limbongan | BR12: Rantau Panjang | BS12: Wakaf Bharu | BW12: Setapak | CA12: Lurah Bilut | CB12: Kuala Bera | CD12: The | CF12: Bandar Indera Mahkota | CG12: Penjom | CH12: Sungai Nerek | CI12: Pekan | CJ12: Ulu Dong | CK12: Selendang | CL12: Perak | CN12: Seberang Perai Utara | CR12: Mukim 7 | CS12: Mukim 6 | CT12: Mukim 7 | CV12: Bandaraya Georgetown | EL12: Bruit | EP12: Bako | EU12: Long Akah | FE12: Engsengel | FF12: 9 Bgd | FI12: 3 Bgd | FM12: Kuang | FN12: Ulu Semenyih | FO12: Peretak | FP12: Meru | FQ12: Jugra | FR12: Sungai Terap | FS12: Batu Arang | FU12: Sekinchan | FW12: KLIA | FZ12: Kuala Besut | GA12: Kumpal | GB12: Hulu Berang | GC12: Kijal | GF12: Cendering | GG12: Rhu Rendang | GH12: Hulu Nerus | GJ12: Ulu Bernam Timor | GK12: Sungai Durian | GL12: Pengkalan Hulu | GN12: Selinsing | GO12: Ulu Kinta | GP12: Saiong | GQ12: Pengkalan Aor | GR12: Pangkor | GT12: Lambor Kanan | GY12: Kechor
B13: Pulau Pinang | D13: Muar | E13: Padang Terap | G13: Rembau | H13: Pasir Mas | K13: Maran | L13: Sungai Ara | N13: Kota Marudu | O13: Dalat | P13: Petaling | Q13: Marang | R13: Larut dan Matang | U13: Simpang Kanan | V13: Tebrau | W13: Ulu Benut | X13: Tanjong Surat | Z13: Ledang | AA13: Padang Endau | AB13: Parit Jawa | AC13: Rimba Terjun | AD13: Gemas | AF13: Telui Kanan | AG13: Bandar Baharu | AH13: Kangkong | AI13: Pekula | AJ13: Jitra | AK13: Naga Lilit | AL13: Pulau Tuba | AM13: Padang Terap Kiri | AN13: Tobiar | AP13: Gulau | AR13: Pauh | AT13: Gadek | AU13: Jus | AV13: Bukit Katil | AZ13: Hulu Teriang | BA13: Bahau | BB13: Sri Menanti | BD13: Rembau | BE13: Legong Hulu | BF13: Setul | BG13: Tampin | BI13: Tawang | BJ13: Pasir Linggi | BK13: 8 BGD | BM13: Kubang Kerian | BN13: Slow | BO13: Takil | BP13: Kubang Sepat | BQ13: Semerak | BR13: Pasir Mas | BS13: Kota Bharu | BW13: Ulu Kelang | CA13: Kemansul | CB13: Kemayan | CD13: Tembeling | CF13: Kuantan | CG13: Tanjong Besar | CH13: Sri Makmur | CI13: Penyor | CJ13: Raub | CK13: Selancar | CL13: Sanggang | CN13: Sungai Ara | CR13: Mukim 8 | CS13: Mukim 7 | CT13: Mukim 8 | CV13: Jalan Perak | EL13: Betanak | EP13: 3 Bgd | EU13: Long Banga | FE13: Bunan Gega | FM13: Kepong | FN13: Hulu Langat | FO13: Rasa | FP13: Rantau Panjang | FQ13: Banting | FR13: Pasangan | FS13: Sungai Buloh | FU13: Sungai Air Tawar | FW13: Sungai Pelek | FZ13: Kubang Bemban | GA13: Pasir Raja | GB13: Hulu Telemung | GC13: Pasir Semut | GF13: Gelugur Kedai | GG13: Pengkalan Berangan | GH13: Bandar Permaisuri | GJ13: Tapah | GK13: Sungai Manik | GL13: Lenggong | GN13: Tanjong Piandang | GO13: Ipoh | GP13: Senggang | GQ13: Selama | GR13: Pantai Remis | GT13: Lambor Kiri | GY13: Kuala Perlis
B14: Putrajaya | D14: Pontian | E14: Pendang | G14: Seremban | H14: Pasir Puteh | K14: Pekan | L14: Timur Laut | N14: Kuala Penyu | O14: Daro | P14: Rawang | Q14: Setiu | R14: Manjung | U14: Simpang Kiri | V14: Bandar Baru Uda | W14: Mahkota | X14: Ulu Sungai Johor | Z14: Sungai Mati | AA14: Pulau Babi | AB14: Sri Menanti | AC14: Ayer Masin | AD14: Pogoh | AF14: Kampung Lalang | AH14: Kota Setar | AI14: Pinang Tunggal | AJ14: Kepelu | AK14: Padang China | AL14: Teluk Yu | AM14: Pedu | AN14: Sungai Tiang | AP14: Jeniang | AR14: Sungai Limau | AT14: Kelemak | AU14: Kesang | AV14: Bukit Lintang | AZ14: Pasoh | BA14: Simpang Pertang | BB14: Terachi | BD14: Gemas | BE14: Miku | BF14: Bandar Seremban | BG14: Ulu Rokan | BI14: Mentuan | BJ14: Pasir Tumboh | BM14: Ketereh | BN14: Karangan | BO14: Pasir Puteh | BP14: Pasir Mas | BQ14: Gong Serapat | BR14: Kemahang | BS14: Palekbang | BW14: Sungai Besi | CA14: Karak | CB14: Gemas | CD14: Ulu Cheka | CF14: Pekan | CG14: Telang | CH14: Sari Awah | CI14: Pulau Manis | CJ14: Ulu Sungai | CK14: Sawira | CL14: Semantan | CN14: Timur Laut | CR14: Mukim 9 | CS14: Mukim 8 | CT14: Mukim 9 | CV14: Jelutong | EL14: Belawai | EP14: 3 SKN RAJD | EU14: Ulu Baram | FM14: Ulu Selangor | FN14: Serdang | FO14: Serendah | FQ14: Jenjarum | FR14: Puncak Alam | FS14: Serdang | FU14: Bagan Terap | FW14: Sungai Merab | FZ14: Lubok Kawah | GA14: Rasau | GB14: Hulu Terengganu | GC14: Tebak | GF14: Gelugur Raja | GG14: Padang Serai | GH14: Sungai Tong | GJ14: Slim River | GK14: Telok Baharu | GL14: Temelong | GN14: Taiping | GO14: Batu Gajah | GP14: Sungai Siput | GQ14: Simpang | GR14: Air Tawar | GT14: Layang-Layang | GY14: Kurong Anai
B15: Sabah | D15: Segamat | E15: Pokok Sena | G15: Tampin | H15: Tanah Merah | K15: Raub | N15: Kudat | O15: Julau | P15: Sabak Bernam | R15: Pengkalan Hulu | U15: Sri Gading | V15: Kota Iskandar | W15: Mengkibol | X15: Ulu Sungei Sedili Besar | Z15: Telok Bakong | AA15: Pulau Pemanggil | AB15: Sungai Balang | AC15: Sungai Karang | AD15: Labis | AF15: Kuala Ketil | AH15: Kuala Kedah | AI15: Rantau Panjang | AJ15: Kubang Pasu | AK15: Padang Meha | AL15: Bukit Malut | AM15: Tekai | AN15: Seberang Pendang | AP15: Kesum | AR15: Sungai Limau Dalam | AT15: Kemuning | AU15: Merlimau | AV15: Bukit Piatu | AZ15: Ulu Triang | BA15: Jelebu | BB15: Ulu Jempol | BD15: Sungai Raya | BE15: Nerasau | BF15: Seremban 2 | BG15: Sungai Kelamah | BI15: Telong | BJ15: Machang | BM15: Lundang | BN15: Kuala Nal | BO15: Kuala Krai | BP15: Rantau Panjang | BQ15: Pasir Puteh | BR15: Gual Ipoh | BW15: Sentul | CA15: Genting Highlands | CB15: Durian Tawar | CD15: Ulu Tembeling | CF15: Rompin | CG15: Ulu Jelai | CH15: Paloh Hinai | CI15: Pulau Rusa | CJ15: Ulu Renggol | CK15: Pianggu | CL15: Songsang | CN15: Barat Daya | CR15: Mukim 10 | CS15: Mukim 9 | CT15: Mukim 10 | CV15: Lebuh Downing | EP15: 71 BN KPD | FM15: Sungai Serai | FN15: Sungai Tekali | FO15: Sungai Gumut | FQ15: KLIA | FR15: Sungai Kajang | FS15: Puchong | FU15: Sabak Bernam | FW15: Meranti | FZ15: Pasir Akar | GA15: Sura | GB15: Mengkawang | GC15: Teluk Kalung | GF15: Kuala Ibai | GG15: Wakaf tapai | GH15: Kampung Guntong Luar & Dalam | GJ15: Temoh | GK15: Teluk Intan | GL15: Temengor | GN15: Kerian | GO15: Manjoi | GP15: Kuala Kangsar | GQ15: Sungai Limau | GR15: Manjung | GT15: Pasir Panjang Ulu | GY15: Kurong Batang
B16: Sarawak | E16: Sik | H16: Tumpat | K16: Rompin | N16: Kunak | O16: Kanowit | P16: Selatan Selangor | R16: Perak Tengah | U16: Sri Medan | V16: Nusajaya | W16: Batu Pahat | X16: Nam Heng | Z16: Teluk Rimba | AA16: Pulau Sibu | AB16: Sungai Raya | AC16: Serkat | AD16: Bekok | AF16: Malau | AH16: Kubang Rotan | AI16: Semeling | AJ16: Malau | AK16: Sedim | AL16: BUKIT MALUT | AM16: Tolak | AN16: Tokai | AP16: Lubuk Tualang | AR16: Ulu Sedaka | AT16: Kuala Linggi | AU16: Nyalas | AV16: Bukit Rambai | AZ16: Ulu Jelebu | BA16: Sungai Lui | BB16: Ulu Muar | BD16: Pengkalan Kempas | BE16: Pedas | BF16: Senawang | BG16: Sungai Jernih | BI16: Tanjung Pauh | BJ16: Sungai Terah | BM16: Pangkal Kalong | BN16: Tanjung Kala | BO16: Binjai | BP16: Kota Bharu | BQ16: Selising | BR16: Bechah Laut | BW16: Dang Wangi | CA16: Bukit Tinggi | CB16: Bukit Kepayang | CD16: Jerantut | CF16: Gebeng | CG16: Benta | CH16: Maran | CI16: Temai | CJ16: Ulu Gali | CK16: Kuala Rompin | CL16: Temerloh | CN16: Bukit Gedong | CR16: Mukim 11 | CS16: Mukim 10 | CT16: Mukim 11 | CV16: Timur Laut | FM16: 12 BGD | FN16: Sungai Ramal | FO16: Sungai Tinggi | FQ16: Tanjung Sepat | FR16: Semarak | FS16: Kelana Jaya | FU16: Sungai Limau | FW16: Jenderam | FZ16: Pelagat | GA16: Hulu Paka | GB16: Menerong | GC16: Hulu Cukai | GF16: Kuala Nerus | GG16: Marang | GH16: Kampung Che Mohid | GJ16: Trolak | GK16: Jenderata | GL16: Kroh | GN16: Alor Pongsu | GO16: Tanjung Rambutan | GP16: Ipoh | GQ16: Sungai Tinggi | GR16: Segari | GT16: Pasir Salak | GY16: Ngolang
B17: Selangor | E17: Sungai Petani | K17: Temerloh | N17: Lahad Datu | O17: Kapit | P17: Sepang | R17: Taiping | U17: Sungai Kluang | V17: Skudai | W17: Kampung Masjid Lama | X17: Mersing | AA17: Pulai Tinggi | AB17: Kg Bukit Pasir | AC17: Pasong | AD17: Chaah | AF17: Parit Panjang | AH17: Langgar | AI17: Sidam Kiri | AJ17: Naga | AK17: Sidam Kanan | AM17: Kuala Nerang | AN17: Charuk Kudong | AP17: Teloi Timur | AT17: Kuala Sungei Baru | AU17: Rim | AV17: Cheng | AZ17: Titi | BA17: Serting | BB17: Ulu Pilah | BD17: Bagan Pinag | BE17: Pilin | BF17: Mantin | BG17: Pasir Besar | BI17: Bachok | BJ17: Pulai | BM17: Panji | BN17: Pasir Era | BO17: Ayer Lanas | BP17: Tok Uban | BQ17: Machang | BR17: Batu Gajah | BW17: Brickfields | CD17: Sungai Tekam | CF17: Tanjung Lumpur | CG17: Titom | CH17: Machang Gelap | CI17: Chini | CJ17: Ulu Atok | CK17: Kedaik | CL17: Maran | CN17: Butterworth | CR17: Mukim 12 | CS17: Mukim 11 | CT17: Mukim 12 | CV17: Tanjung Bungah | FN17: Sungai Lui | FO17: Ulu Bernam | FQ17: Bagan Pasir | FR17: Pantai Remis | FS17: Jalan Klang Lama | FU17: Parit Baru | FZ17: Pengkalan Nangka | GA17: Rantau Abang | GB17: Ajil | GC17: Hulu Jabur | GF17: Kubang Parit | GG17: Jerangau | GH17: Chalok | GJ17: Kamunting | GK17: Tapah | GL17: Taiping | GO17: Bercham | GP17: Tasek Chenderoh | GQ17: Terong | GR17: Pasir Panjang | GT17: Pulau Tiga | GY17: Oran
B18: Terengganu | E18: Yan | N18: Nabawan | O18: Kuching | P18: Sungai Buloh | U18: Sungai Punggor | V18: Pengkalan Rinting | W18: Ulu Belitong | X18: Air Tawar | AA18: Pulau Aur | AB18: Sungai Terap | AC18: Pekan Nenas | AD18: Kampung Gubah | AF18: Telok Teduri | AH18: Lengkuas | AI18: Simpor | AJ18: Padang Perahu | AK18: Sungai Seluang | AM18: Lubok Merbau | AN18: Padang Durian | AP18: Tupai | AT18: Lendu | AU18: Sebatu | AV18: Duyong | AZ18: Simpang Durian | BA18: Palong | BB18: Tanjong ipoh | BD18: Bagan Pinang | BE18: Selemak | BF18: Ulu Jimah | BG18: Padang Lebar | BI18: Kota Bharu | BJ18: Lebir | BM18: Pendek | BN18: Pasir Kelang | BP18: Tendong | BQ18: Wakaf Bunut | BR18: Batang Merbau | BW18: MPLTD | CD18: Sungai Retang | CF18: Paya Bungor | CG18: Sungai Koyan | CH18: Lubuk Paku | CI18: Tanjong Selangor | CJ18: Tersang | CK18: Bukit Setongkol | CL18: Bera | CN18: Lebuh Fell | CR18: Mukim 13 | CS18: Mukim 12 | CT18: Mukim 13 | CV18: Mukim 13 | FN18: Broga | FO18: Ulu Yam | FQ18: Teluk Bunut | FZ18: Pulau Perhentian | GA18: Dungun | GC18: Air Putih | GF18: Kepung | GH18: Gong Terap | GJ18: Jambai | GK18: Sungai Sumun | GL18: Pasir Puteh | GO18: Kepayang | GP18: Siputeh | GQ18: Tupai | GR18: Panchor | GT18: Seri Iskandar | GY18: Padang Pauh
B19: Perak | N19: Papar | O19: Lawas | U19: Tanjong Sembrong | V19: Tanjung Puteri | W19: Parit Ismail | X19: Bandar Mas | AA19: Sembrong | AB19: Tangkak | AC19: Teluk Karang | AD19: Pemanis | AH19: Lepai | AI19: Sungai Pasir | AJ19: Pelubang | AK19: Sungai Ular | AM19: Naka | AN19: Pendang | AT19: Machap | AU19: Selandar | AV19: Kandang | AZ19: Rangoi | BA19: Ladang Gaddes | BB19: Talang | BD19: 1 Bgd | BE19: Semerbok | BF19: Sendayan | BG19: Bukit Rokan | BI19: Balai | BJ19: Kesedar | BM19: Peringat | BN19: Sungai Taku | BP19: Panji | BQ19: Tok Bali | BR19: Alor Pasir | BW19: 4 Div | CD19: Sungai Putat | CF19: Lepar Hilir | CG19: Sinderit | CH19: Bukit Tajau | CI19: Tanjong Pulai | CJ19: Sungai Ruan | CK19: Bukit Ibam | CL19: Bandar Tun Razak | CN19: Seberang Perai Selatan | CR19: Mukim 14 | CS19: Mukim 13 | CT19: Mukim 14 | CV19: Lebuh Muntri | FN19: Batu 14 | FO19: Kuala Kubu Bharu | FQ19: Sungai Lang | FZ19: Tembila | GA19: Kampung Jongok Batu | GC19: Kemaman | GF19: Losong | GH19: Kampung Payong | GJ19: Gunung Besout | GK19: Sungai Pergam | GL19: Papulut | GO19: Tronoh | GP19: Sayong | GQ19: Ulu Selama | GR19: Changkat Kruing | GT19: Parit | GY19: Padang Siding
B20: Perlis | N20: Penampang | O20: Limbang | U20: Bandar MITC | V20: Stulang | W20: Ulu Penggeli | X20: Bandar Penawar | AA20: Lenggor | AB20: Bakri | AD20: Kemelah | AH20: Limbong | AI20: Sungai Petani | AJ20: Pering | AK20: Terap | AM20: Nako Nambua | AN20: Tanah Merah | AT20: Masjid Tanah | AU20: Sempang | AV20: Klebang Besar | AZ20: Kuala Jerang | BA20: Jempol | BB20: Sungai Dua | BE20: Spri | BF20: Pajam | BG20: Bengkahulu | BI20: Beris Panchor | BJ20: Jeram Tekoh | BM20: Salor | BN20: Temalir | BP20: Pangkal Kala | BQ20: Sungai Petai | BW20: Batu Kentonmen | CD20: Sungai Lekok | CF20: Cherok Paloh | CG20: Padang Tengku | CH20: Kuantan | CI20: Runchang | CJ20: Sungai Klau | CK20: Bandar Tun Razak | CL20: Jerantut | CN20: Seberang Perai Tengah | CR20: Mukim 15 | CS20: Mukim 14 | CT20: Mukim 15 | CV20: Jalan Macalister | FN20: Bangi | FO20: Ulu Kalong | FQ20: Sijangkang | FZ20: Tenang | GA20: Kampung Santong | GC20: Paya Berenjut | GF20: Manir | GH20: Bukit Aman | GJ20: Guntung | GK20: Simpang Empat | GL20: Hulu perak | GO20: Pasir Pinji | GP20: Sauk | GQ20: Taiping | GT20: Lambor | GY20: Paya
N21: Pensiangan | O21: Lubok Antu | U21: Parit Raja | V21: Permas | W21: 7 BGD | X21: Bukit Besar | AA21: Endau | AB21: Parit Keroma | AD21: Tenang | AH21: Mergong | AI21: Telui Kiri | AJ21: Putat | AK21: Baling | AM21: Padang Chenderai | AT21: Melaka Pindah | AU21: Semujok | AV21: Klebang Kechil | AZ21: jelebu | BA21: Bukit Rokan | BB21: Padang Lebar | BE21: Tanjong Keling | BF21: Mambau | BG21: 1 Bgd | BI21: Wakaf Aik | BJ21: Aring | BM21: Sering | BN21: Kampong Keroh | BP21: Meranti | BQ21: Nara | BW21: Genting Klang | CD21: Padang Piol | CF21: Cherating | CG21: Merapoh | CI21: Pulau Jawa | CJ21: Sungai Chetang | CK21: Kuantan | CL21: Bentong | CN21: Seberang Perai Utara | CR21: Mukim 16 | CS21: Mukim 15 | CT21: Mukim 16 | CV21: Bukit Jambul | FN21: Balakong | FO21: Sungai Selisek | FQ21: Permatang Pasir | FZ21: Hulu Besut | GA21: Kampung Ladang Gajah Mati | GC21: Pasir Gajah | GF21: Paluh | GH21: Bukit Mundok | GJ21: Changkat Sulaiman | GK21: Padang Tembak | GL21: Bukit Sapi | GO21: Menglembu | GP21: Padang Rengas | GQ21: Matang | GT21: Manjung | GY21: Sanglang
N22: Pitas | O22: Lundu | U22: Bandar Penggaram | V22: Tiram | W22: 8 SKN RAJD | X22: Bukit Waha | AA22: 21 GGK | AB22: Muar | AD22: Bandar Putra | AH22: Padang Hang | AI22: Bedong | AJ22: Sanglang | AK22: Bandar Baharu Serdang | AM22: Padang Sanai | AT22: Melekek | AU22: Serkam | AV22: Krubong | AZ22: Durian Tipus | BA22: Air Hitam | BB22: Melang | BE22: Titian Bintangor | BF22: Linggi | BI22: Tok Bali | BM22: Kota Bharu | BN22: Aur Duri | BP22: Lubok Tapah | BQ22: Jerteh | BW22: 91 REJ BINA RAJD | CD22: Lepar Utara | CF22: Bukit Sagu | CG22: Mela | CI22: Peramu Jaya | CJ22: Lembah Klau | CL22: Genting Highlands | CN22: Sungai Ara | CR22: Seberang Perai Selatan | CS22: Mukim 16 | CT22: Seberang Perai Utara | CV22: Bukit Bendera | FO22: Permatang Pasir | FQ22: Kuala Langat | FZ22: Jerteh | GA22: Felda Kerteh 4 | GC22: Kuala Kemaman | GF22: Pengadang Buluh | GH22: Alor Lek | GJ22: Changkat Jong | GK22: Langkap | GL22: Beng | GO22: Malim Nawar | GP22: Karai | GQ22: Ulu Mengkuang | GT22: Changkat Melintang | GY22: Sena
N23: Ranau | O23: Marudi | U23: Semerah | V23: Johor Jaya | W23: IKEM | X23: Lok Heng | AB23: Segamat | AD23: Batu Anam | AH23: Padang Lalang | AI23: Kota Kuala Muda | AJ23: Sungai Laka | AK23: Merbau Pulas | AM23: Padang Terap | AT23: Padang Sebang | AU23: Sungei Rambai | AV23: Padang Semabok | AZ23: Chennah | BB23: Kuala Pilah | BE23: Rembau | BF23: Jijan | BI23: Pantai Baru | BM23: Pengkalan Chepa | BN23: Mambong | BP23: Kubang Kual | BQ23: Jelor | BW23: 92 SKN SIMP RAJD | CD23: Kuala Tahan | CF23: Bukit Kuantan | CG23: Lubok Kulit | CI23: Pasir Panjang | CJ23: Cheroh | CL23: Ulu Lebu | CN23: Timur Laut | CR23: Sungai Bakap | CS23: Mukim 17 | CT23: Butterworth | FO23: Jalan Sungai Panjang | FQ23: Bukit Sanggang | FZ23: Keruak | GA23: Paka | GC23: Cheneh | GF23: Pulau-Pulau | GH23: Kampung Bukit | GJ23: Behrang | GK23: Hilir PErak | GL23: 2 Bgd | GO23: Kinta | GP23: Batu Hampar | GQ23: Sungai Kerang | GT23: Ulu Dedap | GY23: Seriap
N24: Sandakan | O24: Matu | U24: Pt Yaani | V24: Puteri Wangsa | X24: Sening | AB24: Bandar Maharani | AD24: Jalan Muar | AH24: Pengkalan Kundor | AI24: Kuala Kedah | AJ24: Temin | AK24: Padang Serai | AT24: Parit Melana | AU24: Tedong | AV24: Padang Temu | BB24: Jelai | BE24: Linggi | BF24: Broga | BI24: Kubor Besar | BM24: Wakaf Stan | BN24: Chegar Pinggang | BP24: Jejawi | BQ24: Golok | BW24: 12 Bde | CD24: Kota Gelanggi | CF24: Alor Batu | CG24: Lenjang | CI24: Paloh Hinai | CJ24: Buntu | CL24: Triang | CR24: Simpang Ampat | CS24: Mukim 18 | CT24: Kepala Batas | FO24: Hulu Selangor | FZ24: Besut | GA24: Nerang | GF24: Pulau Redang | GH24: Kampung Pak Ba | GJ24: Batu Melintang | GK24: Chenderong Balai | GO24: Gunung Rapat | GQ24: Sungai Bayor | GT24: Tanjung Tualang | GY24: Sungai Adam
N25: Semporna | O25: Meradong | U25: Yong Peng | V25: Kempas | X25: Tanjong Sedili | AB25: Pagoh | AD25: Tasik Alai | AH25: Pumpong | AI25: Kuala Muda | AJ25: Tunjang | AK25: Pegaga | AT25: Pegoh | AU25: Umbai | AV25: Paya Rumput | BB25: Desa Beting | BE25: Pulau Mampat | BF25: 1 Bgd | BI25: Bertam | BM25: Pintu Geng | BN25: Chenulang | BP25: Cherang Hangus | BQ25: Gaal | CD25: Bandar Tun Razak | CF25: Alor Akar | CG25: Kuala Medang | CI25: Padang Rumbia | CJ25: Bukit Pampong | CL25: Paya Pulai | CR25: Berapit | CS25: Mukim 19 | CT25: Bagan Luar | FZ25: Kota Putera | GA25: Ketengah Jaya | GF25: Rengas | GH25: Bukit Nenas | GJ25: Tanjung Malim | GK25: Bidor | GO25: Gopeng | GQ25: Repoh | GT25: Siputeh | GY25: Titi Tinggi
N26: Sipitang | O26: Miri | U26: Semarang | V26: Pontian | X26: Bukit Ramun | AB26: Parit Yusof | AD26: Segamat | AH26: Sala Kechil | AI26: Kuala Sim | AJ26: Wang Tepus | AK26: Serdang | AT26: Pulau Sebang | AU26: Asahan | AV26: Pringgit | BB26: Betong | BE26: Lubok China | BF26: Sikamat | BM26: Pengkalan feri | BN26: Batu Jong | BP26: Bukit Perah | BQ26: Dalam Rhu | CD26: Damak | CF26: Tanjung Gelang | CG26: Jerkoh | CI26: Nenasi | CJ26: Bukit Fraser | CL26: Padang Tenggala | CR26: Panchor | CS26: Mukim 20 | CT26: Mak Mandin | GA26: Bukit Besi | GF26: Serada | GH26: Kampung Langkap | GK26: Bagan Pasir | GO26: Chemor | GQ26: Rantau Panjang | GT26: Sayong | GY26: Utan Aji
N27: Sook | O27: Muara Tuang | U27: Senggarang | V27: Tampoi | X27: Linggiu | AB27: Batu | AD27: Yong Peng | AH27: Sungai Baharu | AI27: Lubuk Saga | AJ27: Ayer Hitam | AK27: Sungai Kob | AT27: Ramuan China Besar | AU27: Bemban | AV27: Pernu | BB27: Batu Kikir | BM27: Pangkalan Datu | BN27: Kampung Bedal | BQ27: Dalam Huma | CD27: Bukit Genting | CF27: 11 SKN RAJD | CG27: Jeransang | CI27: Muadzam Shah | CJ27: Bentong | CL27: Lanchang | CR27: Mukim 17 | CS27: Mukim 21 | GA27: Alor Tembusu | GF27: Tok Jamal | GH27: Setiu | GO27: Changkat Jong | GQ27: Pulau Pasir Hitam | GT27: Rantau Panjang | GY27: Wang Bintong
N28: Tambunan | O28: Mukah | U28: Rengit | V28: Gelang Patah | X28: Semencu | AB28: Kampong Raja | AH28: Tajar | AI28: Pantai Perai | AJ28: Banai | AT28: Ramuan China Kechil | AU28: Machap | AV28: Semabok | BB28: 1 Bgd | BM28: Panchor | BN28: Bahagia | BQ28: Cherang Ruku | CD28: Bukit Dinding | CF28: 12 RAMD | CG28: Chegar Perah | CI28: Marhum | CL28: Kuala Tekal | CR28: Bandar Tasek Mutiara | CS28: Seberang Perai Tengah | GA28: Ajil | GF28: Bandar Kuala Terengganu | GH28: Sri Langkap | GO28: Buntung | GQ28: Pondok Tanjung | GT28: Perak Tengah | GY28: Kangar
N29: Tawau | O29: Pakan | U29: Batu Pahat | V29: Larkin | X29: Sungai Lebam | AB29: Parit Payong | AH29: Tebengau | AI29: Selambau | AJ29: Bukit Kayu Hitam | AT29: Rembia | AU29: Kemendor | AV29: Sungai Udang | BM29: Kubang Kiat | BN29: Kampung Seladang | BQ29: Bukit Merbau | CD29: 8 RAMD | CF29: 4 BGD (MEK) | CG29: Bukit Betong | CI29: Lepar Hilir | CL29: Kuala Krau | CR29: Jawi | CS29: Permatang pauh | GF29: Seberang Takir | GO29: Bukit Pekan | GQ29: Pantai Remis | GT29: Changkat Lada | GY29: Padang Besar
N30: Teluk Sepanggar | O30: Samarahan | U30: Ayer Hitam | V30: Masai | X30: Sungai Sayong | AB30: Parit Tengah | AH30: Telaga Mas | AI30: Sik | AJ30: Changloon | AT30: Sungei Baru Ilir | AU30: Simpang Kerayong | AV30: Tangga Batu | BM30: Kuala Krai | BN30: Kampung Mia | BQ30: Gong Kedak | CF30: Tanjung Gelang | CG30: Betau | CI30: Kuantan | CL30: Kuala Kaung | CS30: Seberang Jaya | GF30: Ladang Sentosa | GO30: Bemban | GQ30: Larut dan Matang | GT30: Sri Iskandar | GY30: Simpang Empat
N31: Telupid | O31: Saratok | U31: Jalan Perak | V31: Tanjong Langsat | X31: Sungai Sibol | AH31: Telok Chengai | AI31: Sungai Lalang | AJ31: Guar Napai | AT31: Sungei Baru Tengah | AU31: Parit Penghulu | AV31: Tanjong Keling | BM31: Kedai Lalat | BN31: Machang | CL31: Kerdau | CS31: Bukit Mertajam | GF31: Hulu Terengganu | GO31: Telok Medan | GQ31: Kubu Gajah | GY31: Kaki Bukit
N32: Tenom | O32: Sarikei | U32: Kampung Pegawai | V32: Kota Masai | X32: Teluk Ramunia | AH32: Telok Kechai | AI32: Sungai Layang Hujung | AJ32: Kepala Batas | AT32: Sungei Baru Ulu | AU32: 1 Bgd | AV32: Tanjong Minyak | BM32: Kok Lanas | BN32: Telekong | CL32: Kuala Karu | GF32: Besut | GO32: Sungai Labu | GQ32: Kuala Sepetang | GY32: Wilayah Utara
N33: Tongod | O33: Serian | U33: Parit Sulong | X33: Tenggarong | AH33: Titi Gajah | AI33: Tikam Batu | AJ33: Kodiang | AT33: Sungei Buloh | AV33: Telok Mas | BM33: Gunong | BN33: Pahi | CL33: Kelutut | GF33: Setiu | GO33: Simpang Empat | GQ33: Kampung Pinang
N34: Tuaran | O34: Sibu | U34: Sri Merlong | X34: Tunjuk Laut | AH34: Kubang Pasu | AI34: Batu Lintang | AJ34: Permatang Keriang | AT34: Sungei Petai | AV34: Ujong Pasir | BM34: Gondang | BN34: Kampung Guchil | CL34: Karak | GF34: Marang | GO34: Kubang Kerian | GQ34: Ijok
O35: Simunjan | U35: Tongkang Pechah | AH35: Padang Terap | AI35: MSSSP | AJ35: Permatang Paku | AT35: Sungei Siput | AV35: Bandar Melaka | BM35: Batu Tinggi | CL35: Caruk Putting | GF35: Teluk Ketapang | GO35: Kuala Gula | GQ35: Changkat Jering
O36: Song | U36: Bukit Gambir | AH36: Anak Bukit | AI36: 6 WKSP | AJ36: Serdang | AT36: Taboh Naning | AV36: Hang Tuah Jaya | BM36: 6 SKN RAJD | CL36: Bukit Damar | GF36: Telok Pasu | GO36: Sungai Itek | GQ36: 2 SKN RAJD
O37: Sri Aman | U37: Parit Bilal | AH37: Alor Mengkudu | AI37: 6 SSD | AJ37: Sungai Korok | AT37: Tanjong Rimau | AV37: Kota Laksamana | BM37: 7 SKN RAJD | CL37: Bandar Baru | GF37: Sri Nasek | GO37: Pengkalan Pegoh | GQ37: 1 SKN RAJD
O38: Tatau | U38: Sungai Bekok | AH38: Alor Pudak | AI38: 6 PL BEK | AJ38: Teluk Malek | AT38: Tebong | AV38: Kesidang | BM38: 8 BGD | GF38: Pulau Rusa | GO38: Sungai Rata
U39: Taman Kota | AH39: Bakar Bata | AI39: 6 KPTD | AJ39: BN INF 6 RAMD | AT39: Lesung Batu | AV39: Klebang | GF39: Pulau Bahagia | GO39: Pusing
AH40: Bukit Derang | AI40: 6 KPD | AJ40: 5 RS | AT40: Ayer Limau | AV40: Pantai Kundor | GF40: Padang Hiliran | GO40: Sungai Kinta
AH41: Bukit Payong | AI41: 6 KOD | AT41: Tanjung Bidara | AV41: Bandar Hilir | GF41: Hiliran | GO41: 2 Bgd
AH42: Jalan Putra | AI42: 6 BGD | AT42: Alor Gajah | AV42: Melaka Tengah | GF42: Bukit Tunggal
...

Sheet User Manual
C3: Manual Penggunaan Appendix A - Laporan Semasa Situasi Semasa
C6: Manual Am Mengenai Pengisian Excel
C7: NO | D7: Huraian
C8: 1 | D8: Click sekali pada ruangan yang hendak diisi.
C9: 2 | D9: Satu ruangan dialog (Tool Tips) akan terpapar. Tool Tips akan menunjukkan cara bagaimana ingin mengisi ruangan (column tersebut) diikuti dgn contoh.
C10: 3 | D10: Setiap 'column' dalam excel mempunyai cara berbeza untuk diisi. Sila ikut arahan Tool Tips
C11: 4 | D11: Sila utamakan 'column' yang mempunyai tajuk header berwarna biru. Ini kerana ruangan ini WAJIB diisi. Contoh: 'daerah','nama pusat pemindahan' di helaian "ShelterStatus"
C12: 5 | D12: Ada 'column' yang mempunyai senarai pilihan (drop-down list). Jika ya, sila pilih salah satu data yang betul. Anda dilarang untuk memasukkan data selain dari drop-down list.
C14: Susunan (Sorting) Mengikut Daerah Untuk halaman 'ShelterStatus'
C16: NO | D16: Huraian
C17: 1 | D17: Pilih (highlight) maklumat pusat pemindahan yang terlibat sehingga ke header yang terakhir (Nombor Telefon). Pastikan semua column yang terlibat telah terpilih. Sila kecualikan tajuk (header)
C19: 2 | D19: Right-click pada ruangan yang telah dipilih. Pergi ke menu 'Sort' dan pilih jika anda ingin menaik (A-Z) atau menurun (Z-A)
C20: * | D20: Untuk susunan (sorting) di helaian (sheet) yang lain juga menggunakan teknik yang sama. Yang penting, anda mestilah 'highlight' semua maklumat yang ingin disusun.
C24: Cara Mengisi Helaian 'Damage_Casualties'
C26: NO | D26: Huraian
C27: * | D27: Untuk mengisi bahagian jumlah mangsa yang terlibat untuk kategori tertentu, anda harus mengisi bahagian 'Terperinci' ATAU 'Jantina' sahaja. Bahagian 'Jumlah Keseluruhan' akan dikira dengan sendirinya. Bahagian 'Terperinci' adalah di bahagian kotak merah seperti gambarajah di bawah :
C28: * | D28: Jika anda tidak mengetahui bahagian 'Terperinci', anda juga boleh mengisi terus di Bahagian 'Jantina'. Ruangan 'Jumlah Keseluruhan' akan dikira secara automatik.

Sheet Ref_Common
B2: < Basic Data 02.Type >
B4: Casualty Type | D4: Casualty Category | H4: Public Property Type | J4: Jenis Pertanian | L4: Sub-Kategori Jenis Pertanian | P4: Mobilization Status | R4: Mobilization Type | T4: Mobilization Logistics | V4: Ownership
B5: Kematian | D5: Sex | E5: Age | F5: Race | H5: Rumah | J5: Pertanian | L5: Pertanian | M5: Penternakan | N5: Perikanan | P5: Preparation | R5: Mencari & Menyelamat | T5: Darat | V5: Persekutuan
B6: Kecederaan | D6: Lelaki | E6: 0~9 | F6: Melayu | H6: Bangunan Pejabat | J6: Penternakan | L6: Padi | M6: Lembu | N6: Kolam | P6: Stand by | R6: Bantuan Perubatan | T6: Air | V6: Daerah
B7: Hilang | D7: Perempuan | E7: 10~19 | F7: Cina | H7: Sekolah | J7: Perikanan | L7: Sayur-sayuran | M7: Kambing | N7: Sangkar | P7: Transfer | R7: Bantuan Makanan | T7: Udara | V7: Mukim
E8: 20~59 | F8: India | H8: Jalan | L8: Buah-Buahan | M8: Ayam | N8: Hatchery | P8: Dismiss | R8: Pengangkutan Darat | V8: Lain-Lain
B9: CasualtyStatus | E9: Over60 | F9: Bumiputera | H9: Jambatan | L9: Tanaman Kontan | M9: Lain-lain | R9: Pengangkutan Air | T9: Land Logistics
B10: Found | F10: Lain-Lain | H10: Premis Kesihatan | L10: Lain-lain | R10: Pengangkutan Udara | T10: Lori/Trak
B11: Still missing | H11: Sistem Perparitan | R11: Sukarelawan | T11: Pacuan 4 roda
B12: Cured | H12: Bekalan Air | R12: Lain-lain Bantuan | T12: Jengkaut
H13: Bekalan Elektrik | T13: Motosikal
H14: Kemudahan Komunikasi | T14: Bas/van
H15: Alam Sekitar | T15: Lain-lain
H16: Lain-lain
H18: Private Property Type
H19: Rumah Kediaman
H20: Premis Perniagaan | T20: Water Logistics
H21: Premis Kesihatan | T21: Bot
H22: Bekalan Elektrik | T22: Sampan
H23: Bekalan Air | T23: Hoover Craft
H24: Kemudahan Komunikasi | T24: Kapal Selam
H25: Alam Sekitar
H26: Lain-lain
T28: Air Logistics
T29: Helikopter
T30: Kapal Terbang
T31: Jet

Sheet Ref_Shelter
C3: Johor
C6: Batu Pahat
C7: Ayer Hitam | D7: Bagan | E7: Bandar Penggaram | F7: Minyak Beku | G7: Parit Raja | H7: Pt Yaani | I7: Rengit | J7: Semarang | K7: Semerah | L7: Senggarang | M7: Simpang Kanan | N7: Sri Medan | O7: Sungai Kluang | P7: Yong Peng
C8: Balairaya Kg Haji Kamisan | D8: TTT | E8: Dewan Melodi | F8: SEK KEB SG. SULUH | G8: Balai Mesjid Jame Al-Taqwa | H8: Sek Agama Sri Bengkal | I8: Sek Keb Sri Ladang | J8: Sek Keb Ayer Hitam | K8: Balairaya Kg Batu Puteh | L8: Sek Keb Kg Bahru | M8: Balairaya Linau Kechil | N8: Dewan Pertubuhan Peladang Kawasan (PPK) | O8: SEK KEB SERI MERLONG | P8: Balai Mesjid Kg Parit
E9: Sek Keb Pt Bilal | G9: Sek Agama Pt Jelutong | H9: Sek Agama Sri Binjai | I9: Sek Keb Sri Merlong | J9: Sek Keb Bukit Kuari | K9: Balairaya Kg Pt Siba | L9: Sek Keb Koris | N9: Dewan Sekolah Menengah Dato Sulaiman | P9: Sek Agama Sri Bertam
E10: Sek Keb Pt Lapis | G10: Sek Agama Sengkuang | H10: Sek Agama Sri Idaman | I10: Sek Keb Sri Perpat | J10: Sek Keb Kota Dalam | K10: Balairaya Kg Sg Kelambu | L10: Sek Keb Pt Kadir | N10: Sek Agama Seri Chomel | P10: Sek Keb Sepakat Jaya
E11: Sek Men Keb Dato Syed Esa | G11: Sek Agama Sri Aman | H11: Sek Agama Sri Telok | I11: Sek Keb Sri Rejo Sari | J11: Sek Keb Pt Bingan | K11: Sek Keb Bandar | L11: Sek Keb Senggarang | N11: Sek Agama Seri Tiga Serangkai | P11: Sek Keb Sri Bertam
E12: Sek Men Keb Tinggi, 83000 Batu Pahat | G12: Sek Keb Pintas Puding | H12: Sek Keb Bindu | I12: Sek Keb Sri Sempurna | J12: Sek Keb Seri Sabak Uni | K12: Sek Keb Gambut Kg Pt Simen | L12: Sek Keb Sri Molek | N12: Sek Agama Sri Chantik | P12: Sek Keb Sri Yong Peng
E13: SJK C Ai Chun 1 | G13: Sek Keb Pt Jelutong | H13: Sek Keb Bkt Rahmat | I13: Sekolah Agama Sri Belahan | J13: Sek Keb Sri Bulan Kg Ghaffar | K13: Sek Keb Lubok | L13: Sek Keb Sri Timbul | N13: Sek Agama Sri Medan | P13: Sek Keb Tmn Seri Kota
E14: SJK C Chern Hwa | G14: Sek Keb Sri Aman | H14: Sek Keb Bukit Soga | I14: SK Sg Tongkang | J14: Sek Keb Sri Bunut | K14: Sek Keb Peserai Batu 2 | L14: SK Minyak Beku | N14: Sek Keb Kg Jawa | P14: Sek Men Dato Seth
G15: Sek Keb Sri Pandan | H15: Sek Keb Sri Bengkal | J15: Sek Keb Sri Pasir | K15: Sek Keb Sg Kajang | L15: SMK Senggarang | N15: Sek Keb Pt Ju | P15: SJK T Ladang Yong Peng
G16: Sek Kebangsaan Parit Raja | H16: Sek Keb Sri Binjai | J16: Sek Keb Sri Paya | K16: Sek Keb Sri Jasa Sepakat | L16: SMK Tengku Mahmud Iskandar | N16: Sek Keb Sejagong | P16: SMK Yong Peng
G17: Sek Vokasional Batu Pahat | H17: Sek Keb Sri Broleh | J17: Sek Keb Sri Tengah | K17: Sek Keb Sri Makmor | L17: SEK AGAMA KORIS | N17: Sek Keb Seri Maimon | P17: SRJK C Yong Peng I & 2
G18: Sekolah Agama Pintas Puding | H18: Sek Keb Sri Idaman | J18: Sek Keb Tg Semberong | K18: Sek Keb Sri Sekawan Desa | N18: Sek Keb Setia Jaya
G19: Sekolah Agama Pintas Raya | H19: Sek Keb Sri Telok | J19: Sekolah Agama Kg Sri Paya | K19: Sek Keb Sri Utama | N19: Sek Keb Sri Chomel
G20: SJK C Panchor | H20: Sek Men Keb Tunku Putra | J20: SJK C Malayan | K20: Sekolah Agama Seri Separap | N20: Sek Keb Sri Medan
G21: SK Seri Pulih | H21: SJK C Pt Buluh | J21: SMK Dato Menteri | K21: SK Penghulu Salleh | N21: Sek Keb Sri Pasir
G22: SK Sri Gading | H22: SJK C Pt Yaani | K22: SK Sri Padang Sari | N22: Sek Keb Sri Sejati
G23: SK Sri Kemajuan | H23: SJK C York Chai | N23: Sek Keb Tenaga Setia
G24: SMK Munshi Sulaiman | N24: Sek Men Keb Sri Medan
G25: SMK Sri Gading | N25: Sekolah Men Agama Parit Sulong
G26: SMK Tun Aminah, Batu 4 | N26: SJK C Chong Hwa
G27: SMK Tun Ismail | N27: SJK C Chong Hwa Kangkar Senangar
N28: SK Permatang Rengas
N29: SK Sri Laksana
N30: SMK Dato Sulaiman
N31: SMK Penghulu Saad
C36: Johor Bahru
C37: Bandar Johor Bahru | D37: Kempas | E37: Nusajaya | F37: Pengkalan Rinting | G37: Permas | H37: Puteri Wangsa | I37: Skudai | J37: Stulang | K37: Tiram
C38: SEK.KEB.NONG CHIK | D38: Balairaya Lurah Kempas | E38: Balairaya Kg Ladang | F38: Balairaya Kg.Tuah Jaya | G38: Dewanraya Masai | H38: Balairaya Kg Baru Sri Aman | I38: Balai PDK Taman Damai Jaya | J38: Balai Raya KDSM | K38: Balai Kemas
E39: Balairaya Kg Pekajang | F39: Sek.Keb. Kg.Pasir | G39: Sek.Keb. Tmn.Rinting 1 | H39: Balairaya Kg Kangkar Tebrau | I39: Masjid Ladang Batu 8 Skudai | J39: Balairaya Setanggi | K39: Balai Raya Air Putih
E40: Balairaya Kg Pok | G40: Sek.Keb.Masai | H40: Balairaya Kg Sinaran Baru | I40: Masjid Ladang Batu 8 ? Skudai | J40: Dewanraya Bakar Batu | K40: Balai Raya Kg Kong Kong
E41: Balairaya Tiram Duku | G41: Sek.Keb.Permas Jaya 1, | H41: Dewan Raya Felda Ulu Tebrau | I41: Masjid Ladang Batu 8 ? Skudai | J41: Sek. Agama KDSM | K41: Balai Raya Kg Mulia
E42: Sek Agama Kg Pulai | H42: Dewanraya Kg Maju Jaya | I42: Pejabat JKR Bt 10 Skudai | K42: Balai Raya Kg Paya
E43: SK Kangkar Pulai | H43: Sek.Agama Kg Maju Jaya | I43: SJK (C) Pu Sze | K43: Balai Raya Kg Perigi Aceh
E44: SK Tg Adang | H44: Sek.Keb.Tmn.Bkt. Mutiara | I44: SK Kg Melayu Bt 10, Skudai | K44: Balai Raya Kg Tanhung Langsat
H45: Sek.Keb.Tmn.Daya 2 | K45: Balai Raya Kg Tengah
H46: SRJK (C ) Pandan | K46: Dewan Raya Kg Pasir Putih
K47: Rumah Panggong Batu 20
K48: Dewan Raya Kg Sungai Tiram
...
